Workbook

Sheet Start Here
B2: Crown Global Nigeria: operations workbook
B3: Products, orders, fulfilment, money and inventory in one place.
B5: HOW TO USE
B6: 0. Growth Plan | C6: Your step-by-step list from today to wholesale. Set each step's Status as you go; progress and the next step update themselves.
B7: 0b. Product Research | C7: List every product idea from the trend research, US and Nigeria. Scores calculate from demand, competition, margin, weight and regulation. The top scores become test products.
B8: 1. Settings | C8: Set the exchange rate and each sales channel's fee. Yellow cells are yours to edit.
B9: 2. Products | C9: Add every product (one row per SKU). Enter costs in blue columns; margins, stock and reorder flags calculate themselves.
B10: 3. Stock In | C10: Log every delivery of stock you receive (from China, a cargo agent or a supplier).
B11: 4. Orders | C11: Log every order from every channel. Update the Status column as the order moves. Fees, product cost and profit calculate themselves.
B12: 5. Expenses | C12: Log ads, samples, packaging, subscriptions and anything else not tied to a single order.
B13: 6. Dashboard | C13: Set the start and end date at the top to see any week or month.
B15: COLOUR KEY
B16: Blue text | C16: You type this in.
B17: Black text | C17: Formula. Don't type over it.
B18: Yellow fill | C18: Settings and key inputs.
B20: RULES THE SHEET USES
B21: Profit counts on delivery | C21: An order only adds profit when its Status is Delivered. Returned and Failed delivery orders count the delivery cost as a loss; the item goes back into stock.
B22: Stock leaves on shipping | C22: Units count as gone from stock once an order is Shipped or Delivered.
B23: Dropship products | C23: Set Stock model to Dropship and the sheet skips stock counts and reorder flags for that product.
B24: Landed cost | C24: Product price + shipping + duty/clearing + other costs, per unit, in Naira. This is the real cost of one item in your hands.
B25: Repeat customers | C25: The Orders tab marks a customer as Repeat when the same phone number has ordered before.
B27: EXAMPLE ROWS | C27: Rows with SKUs starting EX- are examples showing the format. Delete them (or type over them) when you start.

Sheet Growth Plan
A1: Crown Global: growth plan
A2: Work down the list. Update Status as you go; the progress numbers update themselves. Target date and Notes are yours to fill in.
A4: Progress | G4: By phase
B5: Steps done | C5: =COUNTIF($E$18:$E$76,"Done") | G5: Phase | H5: Done
B6: Total steps | C6: =COUNTA($C$18:$C$76) | G6: 0 · Foundation (now – week 1) | H6: =COUNTIF($E$19:$E$25,"Done")&" of "&COUNTA($C$19:$C$25)
B7: Complete | C7: =IF(C6=0,"",C5/C6) | G7: 1 · Data-led product research (weeks 1–2) | H7: =COUNTIF($E$27:$E$32,"Done")&" of "&COUNTA($C$27:$C$32)
B8: Next step | C8: =IFERROR(INDEX($C$18:$C$76,MATCH(1,$I$18:$I$76,0)),"All done") | G8: 2 · Test order (weeks 2–4) | H8: =COUNTIF($E$34:$E$39,"Done")&" of "&COUNTA($C$34:$C$39)
B9: Blocked | C9: =COUNTIF($E$18:$E$76,"Blocked") | G9: 3 · Content and first sales (weeks 3–6) | H9: =COUNTIF($E$41:$E$47,"Done")&" of "&COUNTA($C$41:$C$47)
G10: 4 · Validate and start ads (month 2) | H10: =COUNTIF($E$49:$E$52,"Done")&" of "&COUNTA($C$49:$C$52)
G11: 5 · Store and small stock (month 3) | H11: =COUNTIF($E$54:$E$59,"Done")&" of "&COUNTA($C$54:$C$59)
G12: 6 · Grow channels (months 4–6) | H12: =COUNTIF($E$61:$E$65,"Done")&" of "&COUNTA($C$61:$C$65)
G13: 7 · China trip and bulk buying (end 2026 / early 2027) | H13: =COUNTIF($E$67:$E$70,"Done")&" of "&COUNTA($C$67:$C$70)
G14: 8 · Private label, wholesale, new markets (2027) | H14: =COUNTIF($E$72:$E$76,"Done")&" of "&COUNTA($C$72:$C$76)
A17: # | B17: Phase | C17: Step | D17: Owner | E17: Status | F17: Target date | G17: Done when | H17: Notes | I17: Open
A18: 0 · Foundation (now – week 1)
A19: 1 | B19: 0 · Foundation | C19: Register Crown Global LLC in North Carolina | D19: Hubby | E19: Not started | G19: State filing confirmed | I19: =IF(OR(C19="",E19="Done"),0,1)
A20: 2 | B20: 0 · Foundation | C20: Get EIN and open US business bank account | D20: Hubby | E20: Not started | G20: EIN letter + account open | I20: =IF(OR(C20="",E20="Done"),0,1)
A21: 3 | B21: 0 · Foundation | C21: Register the domain (crownglobalsourcing.com) | D21: Both | E21: Not started | G21: Domain owned by the business | I21: =IF(OR(C21="",E21="Done"),0,1)
A22: 4 | B22: 0 · Foundation | C22: Reserve Crown Global on Instagram, TikTok, Facebook | D22: Me | E22: Not started | G22: All three handles secured | I22: =IF(OR(C22="",E22="Done"),0,1)
A23: 5 | B23: 0 · Foundation | C23: Set up WhatsApp Business: profile, catalogue, auto-replies | D23: Me | E23: Not started | G23: Business profile live | I23: =IF(OR(C23="",E23="Done"),0,1)
A24: 6 | B24: 0 · Foundation | C24: Decide how Crown Global registers in Nigeria (CAC) | D24: Both | E24: Not started | G24: Agreed whose name and how it links to the US company | I24: =IF(OR(C24="",E24="Done"),0,1)
A25: 7 | B25: 0 · Foundation | C25: Agree the first-month budget (Hubby funds) | D25: Hubby | E25: Not started | G25: Amount agreed and sent for samples, store and ads | I25: =IF(OR(C25="",E25="Done"),0,1)
A26: 1 · Data-led product research (weeks 1–2)
A27: 8 | B27: 1 · Data-led product research | C27: US trend research: Helium 10, Amazon best-sellers, Google Trends | D27: Hubby | E27: Not started | G27: 10 candidates added to Product Research | I27: =IF(OR(C27="",E27="Done"),0,1)
A28: 9 | B28: 1 · Data-led product research | C28: Nigeria trend research: Jumia best-sellers, TikTok, Google Trends Nigeria | D28: Me | E28: Not started | G28: 10 candidates added to Product Research | I28: =IF(OR(C28="",E28="Done"),0,1)
A29: 10 | B29: 1 · Data-led product research | C29: Study 10 Lagos Instagram/TikTok vendors selling trending products | D29: Me | E29: Not started | G29: Prices, posting style, common customer questions noted | I29: =IF(OR(C29="",E29="Done"),0,1)
A30: 11 | B30: 1 · Data-led product research | C30: Ask 20 people in your network what they buy and what annoys them | D30: Me | E30: Not started | G30: 20 answers written down | I30: =IF(OR(C30="",E30="Done"),0,1)
A31: 12 | B31: 1 · Data-led product research | C31: Find each candidate on 1688; add factory price, landed cost and weight | D31: Me | E31: Not started | G31: Every candidate has a score | I31: =IF(OR(C31="",E31="Done"),0,1)
A32: 13 | B32: 1 · Data-led product research | C32: Review the scores together; mark the top 3–5 as Test | D32: Both | E32: Not started | G32: Test list agreed; the niche follows the winners | I32: =IF(OR(C32="",E32="Done"),0,1)
A33: 2 · Test order (weeks 2–4)
A34: 14 | B34: 2 · Test order | C34: Move the Test products into the Products tab | D34: Me | E34: Not started | G34: 3–5 products with costs and prices | I34: =IF(OR(C34="",E34="Done"),0,1)
A35: 15 | B35: 2 · Test order | C35: Order samples with 1688 direct shipping to Nigeria | D35: Me | E35: Not started | G35: Order placed, tracking saved | I35: =IF(OR(C35="",E35="Done"),0,1)
A36: 16 | B36: 2 · Test order | C36: Send one small order through a Lagos cargo agent to compare | D36: Me | E36: Not started | G36: Both routes compared on cost and days | I36: =IF(OR(C36="",E36="Done"),0,1)
A37: 17 | B37: 2 · Test order | C37: Take a short importation class; get agent contacts and payment tips | D37: Me | E37: Not started | G37: At least 2 trusted agent contacts | I37: =IF(OR(C37="",E37="Done"),0,1)
A38: 18 | B38: 2 · Test order | C38: Log cost, days and condition in Stock In | D38: Me | E38: Not started | G38: Real landed cost per product known | I38: =IF(OR(C38="",E38="Done"),0,1)
A39: 19 | B39: 2 · Test order | C39: Check quality and packaging; drop anything that fails | D39: Me | E39: Not started | G39: Only products you'd buy yourself remain | I39: =IF(OR(C39="",E39="Done"),0,1)
A40: 3 · Content and first sales (weeks 3–6)
A41: 20 | B41: 3 · Content and first sales | C41: Film 5–10 videos per product: unboxing, how-to, before/after | D41: Me | E41: Not started | G41: At least 15 videos ready | I41: =IF(OR(C41="",E41="Done"),0,1)
A42: 21 | B42: 3 · Content and first sales | C42: Post daily for 2 weeks with no ads | D42: Me | E42: Not started | G42: Know which videos get saves, shares, 'how much?' | I42: =IF(OR(C42="",E42="Done"),0,1)
A43: 22 | B43: 3 · Content and first sales | C43: Open pre-orders for the winners on Instagram and WhatsApp | D43: Me | E43: Not started | G43: Clear message: China pre-order, 2–3 weeks | I43: =IF(OR(C43="",E43="Done"),0,1)
...

Sheet Dashboard
B2: Crown Global Nigeria: dashboard
B4: Period start | C4: 46296 | E4: Change the two yellow dates to see any week or month.
B5: Period end | C5: 46326
B7: MONEY | E7: ORDERS BY CHANNEL
B8: Sales (delivered orders) | C8: =SUMIFS(Orders!$O$2:$O$501,Orders!$K$2:$K$501,"Delivered",Orders!$B$2:$B$501,">="&$C$4,Orders!$B$2:$B$501,"<="&$C$5) | E8: Total orders | F8: =COUNTIFS(Orders!$B$2:$B$501,">="&$C$4,Orders!$B$2:$B$501,"<="&$C$5)
B9: + Delivery fees collected | C9: =SUMIFS(Orders!$M$2:$M$501,Orders!$K$2:$K$501,"Delivered",Orders!$B$2:$B$501,">="&$C$4,Orders!$B$2:$B$501,"<="&$C$5) | E9: Instagram | F9: =COUNTIFS(Orders!$C$2:$C$501,Settings!$A$8,Orders!$B$2:$B$501,">="&$C$4,Orders!$B$2:$B$501,"<="&$C$5)
B10: − Product cost | C10: =SUMIFS(Orders!$Q$2:$Q$501,Orders!$K$2:$K$501,"Delivered",Orders!$B$2:$B$501,">="&$C$4,Orders!$B$2:$B$501,"<="&$C$5) | E10: WhatsApp | F10: =COUNTIFS(Orders!$C$2:$C$501,Settings!$A$9,Orders!$B$2:$B$501,">="&$C$4,Orders!$B$2:$B$501,"<="&$C$5)
B11: − Marketplace & payment fees | C11: =SUMIFS(Orders!$P$2:$P$501,Orders!$K$2:$K$501,"Delivered",Orders!$B$2:$B$501,">="&$C$4,Orders!$B$2:$B$501,"<="&$C$5) | E11: TikTok | F11: =COUNTIFS(Orders!$C$2:$C$501,Settings!$A$10,Orders!$B$2:$B$501,">="&$C$4,Orders!$B$2:$B$501,"<="&$C$5)
B12: − Delivery costs (incl. returns) | C12: =SUMIFS(Orders!$N$2:$N$501,Orders!$K$2:$K$501,"Delivered",Orders!$B$2:$B$501,">="&$C$4,Orders!$B$2:$B$501,"<="&$C$5)+SUMIFS(Orders!$N$2:$N$501,Orders!$K$2:$K$501,"Returned",Orders!$B$2:$B$501,">="&$C$4,Orders!$B$2:$B$501,"<="&$C$5)+SUMIFS(Orders!$N$2:$N$501,Orders!$K$2:$K$501,"Failed delivery",Orders!$B$2:$B$501,">="&$C$4,Orders!$B$2:$B$501,"<="&$C$5) | E12: Website | F12: =COUNTIFS(Orders!$C$2:$C$501,Settings!$A$11,Orders!$B$2:$B$501,">="&$C$4,Orders!$B$2:$B$501,"<="&$C$5)
B13: Profit from orders | C13: =SUMIFS(Orders!$R$2:$R$501,Orders!$B$2:$B$501,">="&$C$4,Orders!$B$2:$B$501,"<="&$C$5) | E13: Jumia | F13: =COUNTIFS(Orders!$C$2:$C$501,Settings!$A$12,Orders!$B$2:$B$501,">="&$C$4,Orders!$B$2:$B$501,"<="&$C$5)
B14: − Ad spend | C14: =SUMIFS(Expenses!$D$2:$D$501,Expenses!$B$2:$B$501,"Ads",Expenses!$A$2:$A$501,">="&$C$4,Expenses!$A$2:$A$501,"<="&$C$5) | E14: Jiji | F14: =COUNTIFS(Orders!$C$2:$C$501,Settings!$A$13,Orders!$B$2:$B$501,">="&$C$4,Orders!$B$2:$B$501,"<="&$C$5)
B15: − Other expenses | C15: =SUMIFS(Expenses!$D$2:$D$501,Expenses!$A$2:$A$501,">="&$C$4,Expenses!$A$2:$A$501,"<="&$C$5)-C14 | E15: Direct | F15: =COUNTIFS(Orders!$C$2:$C$501,Settings!$A$14,Orders!$B$2:$B$501,">="&$C$4,Orders!$B$2:$B$501,"<="&$C$5)
B16: Net profit | C16: =C13-C14-C15 | E16: Other | F16: =COUNTIFS(Orders!$C$2:$C$501,Settings!$A$15,Orders!$B$2:$B$501,">="&$C$4,Orders!$B$2:$B$501,"<="&$C$5)
B17: Net margin on sales | C17: =IF(C8=0,"",C16/C8)
E18: INVENTORY
B19: FULFILMENT | E19: Units in stock | F19: =SUM(Products!$Q$2:$Q$101)
B20: New | C20: =COUNTIFS(Orders!$K$2:$K$501,Settings!$D$19,Orders!$B$2:$B$501,">="&$C$4,Orders!$B$2:$B$501,"<="&$C$5) | E20: Inventory value (at cost) | F20: =SUM(Products!$T$2:$T$101)
B21: Awaiting fulfillment | C21: =COUNTIFS(Orders!$K$2:$K$501,Settings!$D$20,Orders!$B$2:$B$501,">="&$C$4,Orders!$B$2:$B$501,"<="&$C$5) | E21: Products to reorder | F21: =COUNTIF(Products!$S$2:$S$101,"REORDER")
B22: Shipped | C22: =COUNTIFS(Orders!$K$2:$K$501,Settings!$D$21,Orders!$B$2:$B$501,">="&$C$4,Orders!$B$2:$B$501,"<="&$C$5) | E22: Active products | F22: =COUNTA(Products!$A$2:$A$101)
B23: Delivered | C23: =COUNTIFS(Orders!$K$2:$K$501,Settings!$D$22,Orders!$B$2:$B$501,">="&$C$4,Orders!$B$2:$B$501,"<="&$C$5)
B24: Failed delivery | C24: =COUNTIFS(Orders!$K$2:$K$501,Settings!$D$23,Orders!$B$2:$B$501,">="&$C$4,Orders!$B$2:$B$501,"<="&$C$5) | E24: CUSTOMERS
B25: Returned | C25: =COUNTIFS(Orders!$K$2:$K$501,Settings!$D$24,Orders!$B$2:$B$501,">="&$C$4,Orders!$B$2:$B$501,"<="&$C$5) | E25: Orders from new customers | F25: =COUNTIFS(Orders!$S$2:$S$501,"New",Orders!$B$2:$B$501,">="&$C$4,Orders!$B$2:$B$501,"<="&$C$5)
B26: Cancelled | C26: =COUNTIFS(Orders!$K$2:$K$501,Settings!$D$25,Orders!$B$2:$B$501,">="&$C$4,Orders!$B$2:$B$501,"<="&$C$5) | E26: Orders from repeat customers | F26: =COUNTIFS(Orders!$S$2:$S$501,"Repeat",Orders!$B$2:$B$501,">="&$C$4,Orders!$B$2:$B$501,"<="&$C$5)
B27: Return / failed rate | C27: =IF((C23+C24+C25)=0,"",(C24+C25)/(C23+C24+C25)) | E27: Repeat order share | F27: =IF((F25+F26)=0,"",F26/(F25+F26))
E28: Average order value | F28: =IF(COUNTIFS(Orders!$K$2:$K$501,"Delivered",Orders!$B$2:$B$501,">="&$C$4,Orders!$B$2:$B$501,"<="&$C$5)=0,"",C8/COUNTIFS(Orders!$K$2:$K$501,"Delivered",Orders!$B$2:$B$501,">="&$C$4,Orders!$B$2:$B$501,"<="&$C$5))

Sheet Product Research
A1: Product | B1: Found via | C1: Market | D1: Demand signal (what the data shows) | E1: Demand (1–5) | F1: Competition (1–5) | G1: Factory price (₦) | H1: Est. landed cost (₦) | I1: Target price (₦) | J1: Margin % | K1: Weight (g) | L1: Regulated? | M1: Margin score | N1: Shipping score | O1: Total score (max 20) | P1: Decision | Q1: Notes
A2: EX Satin bonnet | B2: Jumia best-sellers | C2: Both | D2: Top 20 in hair accessories; 1,200+ reviews | E2: 5 | F2: 4 | G2: 1400 | H2: 1950 | I2: 7500 | J2: =IF(OR(H2="",I2="",I2=0),"",(I2-H2)/I2) | K2: 60 | L2: No | M2: =IF(J2="","",IF(J2>=0.66,5,IF(J2>=0.5,4,IF(J2>=0.4,3,IF(J2>=0.25,2,1))))) | N2: =IF(K2="","",IF(K2<=100,5,IF(K2<=250,4,IF(K2<=500,3,IF(K2<=1000,2,1))))) | O2: =IF(OR(E2="",F2="",M2="",N2=""),"",E2+(6-F2)+M2+N2-IF(L2="Yes",2,0)) | P2: Test
A3: EX Heatless curling rod | B3: TikTok trend | C3: Both | D3: Trending on TikTok; Helium 10 shows rising US searches | E3: 4 | F3: 2 | G3: 1800 | H3: 2600 | I3: 9000 | J3: =IF(OR(H3="",I3="",I3=0),"",(I3-H3)/I3) | K3: 120 | L3: No | M3: =IF(J3="","",IF(J3>=0.66,5,IF(J3>=0.5,4,IF(J3>=0.4,3,IF(J3>=0.25,2,1))))) | N3: =IF(K3="","",IF(K3<=100,5,IF(K3<=250,4,IF(K3<=500,3,IF(K3<=1000,2,1))))) | O3: =IF(OR(E3="",F3="",M3="",N3=""),"",E3+(6-F3)+M3+N3-IF(L3="Yes",2,0)) | P3: Test
A4: EX Hair growth oil | B4: Instagram vendors | C4: Nigeria | D4: Many vendors, strong comments | E4: 4 | F4: 5 | G4: 2500 | H4: 3500 | I4: 8000 | J4: =IF(OR(H4="",I4="",I4=0),"",(I4-H4)/I4) | K4: 250 | L4: Yes | M4: =IF(J4="","",IF(J4>=0.66,5,IF(J4>=0.5,4,IF(J4>=0.4,3,IF(J4>=0.25,2,1))))) | N4: =IF(K4="","",IF(K4<=100,5,IF(K4<=250,4,IF(K4<=500,3,IF(K4<=1000,2,1))))) | O4: =IF(OR(E4="",F4="",M4="",N4=""),"",E4+(6-F4)+M4+N4-IF(L4="Yes",2,0)) | P4: Drop
J5: =IF(OR(H5="",I5="",I5=0),"",(I5-H5)/I5) | M5: =IF(J5="","",IF(J5>=0.66,5,IF(J5>=0.5,4,IF(J5>=0.4,3,IF(J5>=0.25,2,1))))) | N5: =IF(K5="","",IF(K5<=100,5,IF(K5<=250,4,IF(K5<=500,3,IF(K5<=1000,2,1))))) | O5: =IF(OR(E5="",F5="",M5="",N5=""),"",E5+(6-F5)+M5+N5-IF(L5="Yes",2,0))
J6: =IF(OR(H6="",I6="",I6=0),"",(I6-H6)/I6) | M6: =IF(J6="","",IF(J6>=0.66,5,IF(J6>=0.5,4,IF(J6>=0.4,3,IF(J6>=0.25,2,1))))) | N6: =IF(K6="","",IF(K6<=100,5,IF(K6<=250,4,IF(K6<=500,3,IF(K6<=1000,2,1))))) | O6: =IF(OR(E6="",F6="",M6="",N6=""),"",E6+(6-F6)+M6+N6-IF(L6="Yes",2,0))
J7: =IF(OR(H7="",I7="",I7=0),"",(I7-H7)/I7) | M7: =IF(J7="","",IF(J7>=0.66,5,IF(J7>=0.5,4,IF(J7>=0.4,3,IF(J7>=0.25,2,1))))) | N7: =IF(K7="","",IF(K7<=100,5,IF(K7<=250,4,IF(K7<=500,3,IF(K7<=1000,2,1))))) | O7: =IF(OR(E7="",F7="",M7="",N7=""),"",E7+(6-F7)+M7+N7-IF(L7="Yes",2,0))
J8: =IF(OR(H8="",I8="",I8=0),"",(I8-H8)/I8) | M8: =IF(J8="","",IF(J8>=0.66,5,IF(J8>=0.5,4,IF(J8>=0.4,3,IF(J8>=0.25,2,1))))) | N8: =IF(K8="","",IF(K8<=100,5,IF(K8<=250,4,IF(K8<=500,3,IF(K8<=1000,2,1))))) | O8: =IF(OR(E8="",F8="",M8="",N8=""),"",E8+(6-F8)+M8+N8-IF(L8="Yes",2,0))
J9: =IF(OR(H9="",I9="",I9=0),"",(I9-H9)/I9) | M9: =IF(J9="","",IF(J9>=0.66,5,IF(J9>=0.5,4,IF(J9>=0.4,3,IF(J9>=0.25,2,1))))) | N9: =IF(K9="","",IF(K9<=100,5,IF(K9<=250,4,IF(K9<=500,3,IF(K9<=1000,2,1))))) | O9: =IF(OR(E9="",F9="",M9="",N9=""),"",E9+(6-F9)+M9+N9-IF(L9="Yes",2,0))
J10: =IF(OR(H10="",I10="",I10=0),"",(I10-H10)/I10) | M10: =IF(J10="","",IF(J10>=0.66,5,IF(J10>=0.5,4,IF(J10>=0.4,3,IF(J10>=0.25,2,1))))) | N10: =IF(K10="","",IF(K10<=100,5,IF(K10<=250,4,IF(K10<=500,3,IF(K10<=1000,2,1))))) | O10: =IF(OR(E10="",F10="",M10="",N10=""),"",E10+(6-F10)+M10+N10-IF(L10="Yes",2,0))
J11: =IF(OR(H11="",I11="",I11=0),"",(I11-H11)/I11) | M11: =IF(J11="","",IF(J11>=0.66,5,IF(J11>=0.5,4,IF(J11>=0.4,3,IF(J11>=0.25,2,1))))) | N11: =IF(K11="","",IF(K11<=100,5,IF(K11<=250,4,IF(K11<=500,3,IF(K11<=1000,2,1))))) | O11: =IF(OR(E11="",F11="",M11="",N11=""),"",E11+(6-F11)+M11+N11-IF(L11="Yes",2,0))
J12: =IF(OR(H12="",I12="",I12=0),"",(I12-H12)/I12) | M12: =IF(J12="","",IF(J12>=0.66,5,IF(J12>=0.5,4,IF(J12>=0.4,3,IF(J12>=0.25,2,1))))) | N12: =IF(K12="","",IF(K12<=100,5,IF(K12<=250,4,IF(K12<=500,3,IF(K12<=1000,2,1))))) | O12: =IF(OR(E12="",F12="",M12="",N12=""),"",E12+(6-F12)+M12+N12-IF(L12="Yes",2,0))
J13: =IF(OR(H13="",I13="",I13=0),"",(I13-H13)/I13) | M13: =IF(J13="","",IF(J13>=0.66,5,IF(J13>=0.5,4,IF(J13>=0.4,3,IF(J13>=0.25,2,1))))) | N13: =IF(K13="","",IF(K13<=100,5,IF(K13<=250,4,IF(K13<=500,3,IF(K13<=1000,2,1))))) | O13: =IF(OR(E13="",F13="",M13="",N13=""),"",E13+(6-F13)+M13+N13-IF(L13="Yes",2,0))
J14: =IF(OR(H14="",I14="",I14=0),"",(I14-H14)/I14) | M14: =IF(J14="","",IF(J14>=0.66,5,IF(J14>=0.5,4,IF(J14>=0.4,3,IF(J14>=0.25,2,1))))) | N14: =IF(K14="","",IF(K14<=100,5,IF(K14<=250,4,IF(K14<=500,3,IF(K14<=1000,2,1))))) | O14: =IF(OR(E14="",F14="",M14="",N14=""),"",E14+(6-F14)+M14+N14-IF(L14="Yes",2,0))
J15: =IF(OR(H15="",I15="",I15=0),"",(I15-H15)/I15) | M15: =IF(J15="","",IF(J15>=0.66,5,IF(J15>=0.5,4,IF(J15>=0.4,3,IF(J15>=0.25,2,1))))) | N15: =IF(K15="","",IF(K15<=100,5,IF(K15<=250,4,IF(K15<=500,3,IF(K15<=1000,2,1))))) | O15: =IF(OR(E15="",F15="",M15="",N15=""),"",E15+(6-F15)+M15+N15-IF(L15="Yes",2,0))
J16: =IF(OR(H16="",I16="",I16=0),"",(I16-H16)/I16) | M16: =IF(J16="","",IF(J16>=0.66,5,IF(J16>=0.5,4,IF(J16>=0.4,3,IF(J16>=0.25,2,1))))) | N16: =IF(K16="","",IF(K16<=100,5,IF(K16<=250,4,IF(K16<=500,3,IF(K16<=1000,2,1))))) | O16: =IF(OR(E16="",F16="",M16="",N16=""),"",E16+(6-F16)+M16+N16-IF(L16="Yes",2,0))
... J201: =IF(OR(H201="",I201="",I201=0),"",(I201-H201)/I201) | M201: =IF(J201="","",IF(J201>=0.66,5,IF(J201>=0.5,4,IF(J201>=0.4,3,IF(J201>=0.25,2,1))))) | N201: =IF(K201="","",IF(K201<=100,5,IF(K201<=250,4,IF(K201<=500,3,IF(K201<=1000,2,1))))) | O201: =IF(OR(E201="",F201="",M201="",N201=""),"",E201+(6-F201)+M201+N201-IF(L201="Yes",2,0))

Sheet Settings
A1: Settings
A3: Exchange rate (₦ per US$1) | B3: 1500 | C3: Example value. Update with the rate you actually pay (virtual dollar card or agent rate).
A4: Default reorder point (units) | B4: 20 | C4: Used when a product has no reorder point of its own.
A6: Sales channels
A7: Channel | B7: Fee % per sale | C7: Note
A8: Instagram | B8: 0 | C8: No platform fee on DMs. Ad spend goes in Expenses.
A9: WhatsApp | B9: 0 | C9: No platform fee.
A10: TikTok | B10: 0 | C10: No platform fee on DM sales. Ad spend goes in Expenses.
A11: Website | B11: 0.015 | C11: Example: Paystack local card fee of 1.5% (capped per transaction). Check your processor's current rate.
A12: Jumia | B12: 0.1 | C12: Placeholder. Jumia commission varies by category; check the current rate for yours.
A13: Jiji | B13: 0 | C13: Classifieds: no commission. Paid boosts go in Expenses.
A14: Direct | B14: 0 | C14: Friends, referrals, walk-ins.
A15: Other | B15: 0
A18: Lists used in dropdowns | D18: Order status | E18: Payment status | F18: Expense category | G18: Stock model
D19: New | E19: Paid | F19: Ads | G19: Dropship
D20: Awaiting fulfillment | E20: Pay on delivery | F20: Samples | G20: In stock
D21: Shipped | E21: Unpaid | F21: Packaging
D22: Delivered | E22: Refunded | F22: Storage / fulfilment
D23: Failed delivery | F23: Software / subscriptions
D24: Returned | F24: Marketplace fees
D25: Cancelled | F25: Delivery (not per order)
F26: Other

Sheet Products
A1: SKU | B1: Product name | C1: Supplier | D1: Supplier link | E1: Stock model | F1: Product cost / unit (₦) | G1: Shipping / unit (₦) | H1: Duty & clearing / unit (₦) | I1: Other / unit (₦) | J1: Landed cost / unit (₦) | K1: Selling price (₦) | L1: Profit / unit (₦) | M1: Margin % | N1: Opening stock | O1: Units received | P1: Units shipped / delivered | Q1: Units remaining | R1: Reorder point | S1: Stock status | T1: Inventory value (₦)
A2: EX-BON-01 | B2: Satin bonnet (black) | C2: 1688 seller A | E2: Dropship | F2: 1400 | G2: 300 | H2: 150 | I2: 100 | J2: =IF(A2="","",SUM(F2:I2)) | K2: 7500 | L2: =IF(OR(A2="",K2=""),"",K2-J2) | M2: =IF(OR(A2="",K2="",K2=0),"",L2/K2) | N2: 0 | O2: =IF(A2="","",SUMIFS('Stock In'!$C$2:$C$501,'Stock In'!$B$2:$B$501,A2)) | P2: =IF(A2="","",SUMIFS(Orders!$H$2:$H$501,Orders!$G$2:$G$501,A2,Orders!$K$2:$K$501,"Shipped")+SUMIFS(Orders!$H$2:$H$501,Orders!$G$2:$G$501,A2,Orders!$K$2:$K$501,"Delivered")) | Q2: =IF(OR(A2="",E2="Dropship"),"",N(N2)+N(O2)-N(P2)) | R2: 20 | S2: =IF(OR(A2="",E2="Dropship"),"",IF(Q2<=IF(R2="",Settings!$B$4,R2),"REORDER","OK")) | T2: =IF(OR(A2="",E2="Dropship",J2=""),"",Q2*J2)
A3: EX-EDG-01 | B3: Edge brush set (3 pcs) | C3: 1688 seller B | E3: In stock | F3: 900 | G3: 250 | H3: 100 | I3: 50 | J3: =IF(A3="","",SUM(F3:I3)) | K3: 5000 | L3: =IF(OR(A3="",K3=""),"",K3-J3) | M3: =IF(OR(A3="",K3="",K3=0),"",L3/K3) | N3: 0 | O3: =IF(A3="","",SUMIFS('Stock In'!$C$2:$C$501,'Stock In'!$B$2:$B$501,A3)) | P3: =IF(A3="","",SUMIFS(Orders!$H$2:$H$501,Orders!$G$2:$G$501,A3,Orders!$K$2:$K$501,"Shipped")+SUMIFS(Orders!$H$2:$H$501,Orders!$G$2:$G$501,A3,Orders!$K$2:$K$501,"Delivered")) | Q3: =IF(OR(A3="",E3="Dropship"),"",N(N3)+N(O3)-N(P3)) | R3: 15 | S3: =IF(OR(A3="",E3="Dropship"),"",IF(Q3<=IF(R3="",Settings!$B$4,R3),"REORDER","OK")) | T3: =IF(OR(A3="",E3="Dropship",J3=""),"",Q3*J3)
A4: EX-SCR-01 | B4: Silk scrunchies (5 pack) | C4: 1688 seller C | E4: In stock | F4: 1100 | G4: 200 | H4: 120 | I4: 80 | J4: =IF(A4="","",SUM(F4:I4)) | K4: 6000 | L4: =IF(OR(A4="",K4=""),"",K4-J4) | M4: =IF(OR(A4="",K4="",K4=0),"",L4/K4) | N4: 10 | O4: =IF(A4="","",SUMIFS('Stock In'!$C$2:$C$501,'Stock In'!$B$2:$B$501,A4)) | P4: =IF(A4="","",SUMIFS(Orders!$H$2:$H$501,Orders!$G$2:$G$501,A4,Orders!$K$2:$K$501,"Shipped")+SUMIFS(Orders!$H$2:$H$501,Orders!$G$2:$G$501,A4,Orders!$K$2:$K$501,"Delivered")) | Q4: =IF(OR(A4="",E4="Dropship"),"",N(N4)+N(O4)-N(P4)) | R4: 15 | S4: =IF(OR(A4="",E4="Dropship"),"",IF(Q4<=IF(R4="",Settings!$B$4,R4),"REORDER","OK")) | T4: =IF(OR(A4="",E4="Dropship",J4=""),"",Q4*J4)
J5: =IF(A5="","",SUM(F5:I5)) | L5: =IF(OR(A5="",K5=""),"",K5-J5) | M5: =IF(OR(A5="",K5="",K5=0),"",L5/K5) | O5: =IF(A5="","",SUMIFS('Stock In'!$C$2:$C$501,'Stock In'!$B$2:$B$501,A5)) | P5: =IF(A5="","",SUMIFS(Orders!$H$2:$H$501,Orders!$G$2:$G$501,A5,Orders!$K$2:$K$501,"Shipped")+SUMIFS(Orders!$H$2:$H$501,Orders!$G$2:$G$501,A5,Orders!$K$2:$K$501,"Delivered")) | Q5: =IF(OR(A5="",E5="Dropship"),"",N(N5)+N(O5)-N(P5)) | S5: =IF(OR(A5="",E5="Dropship"),"",IF(Q5<=IF(R5="",Settings!$B$4,R5),"REORDER","OK")) | T5: =IF(OR(A5="",E5="Dropship",J5=""),"",Q5*J5)
J6: =IF(A6="","",SUM(F6:I6)) | L6: =IF(OR(A6="",K6=""),"",K6-J6) | M6: =IF(OR(A6="",K6="",K6=0),"",L6/K6) | O6: =IF(A6="","",SUMIFS('Stock In'!$C$2:$C$501,'Stock In'!$B$2:$B$501,A6)) | P6: =IF(A6="","",SUMIFS(Orders!$H$2:$H$501,Orders!$G$2:$G$501,A6,Orders!$K$2:$K$501,"Shipped")+SUMIFS(Orders!$H$2:$H$501,Orders!$G$2:$G$501,A6,Orders!$K$2:$K$501,"Delivered")) | Q6: =IF(OR(A6="",E6="Dropship"),"",N(N6)+N(O6)-N(P6)) | S6: =IF(OR(A6="",E6="Dropship"),"",IF(Q6<=IF(R6="",Settings!$B$4,R6),"REORDER","OK")) | T6: =IF(OR(A6="",E6="Dropship",J6=""),"",Q6*J6)
J7: =IF(A7="","",SUM(F7:I7)) | L7: =IF(OR(A7="",K7=""),"",K7-J7) | M7: =IF(OR(A7="",K7="",K7=0),"",L7/K7) | O7: =IF(A7="","",SUMIFS('Stock In'!$C$2:$C$501,'Stock In'!$B$2:$B$501,A7)) | P7: =IF(A7="","",SUMIFS(Orders!$H$2:$H$501,Orders!$G$2:$G$501,A7,Orders!$K$2:$K$501,"Shipped")+SUMIFS(Orders!$H$2:$H$501,Orders!$G$2:$G$501,A7,Orders!$K$2:$K$501,"Delivered")) | Q7: =IF(OR(A7="",E7="Dropship"),"",N(N7)+N(O7)-N(P7)) | S7: =IF(OR(A7="",E7="Dropship"),"",IF(Q7<=IF(R7="",Settings!$B$4,R7),"REORDER","OK")) | T7: =IF(OR(A7="",E7="Dropship",J7=""),"",Q7*J7)
J8: =IF(A8="","",SUM(F8:I8)) | L8: =IF(OR(A8="",K8=""),"",K8-J8) | M8: =IF(OR(A8="",K8="",K8=0),"",L8/K8) | O8: =IF(A8="","",SUMIFS('Stock In'!$C$2:$C$501,'Stock In'!$B$2:$B$501,A8)) | P8: =IF(A8="","",SUMIFS(Orders!$H$2:$H$501,Orders!$G$2:$G$501,A8,Orders!$K$2:$K$501,"Shipped")+SUMIFS(Orders!$H$2:$H$501,Orders!$G$2:$G$501,A8,Orders!$K$2:$K$501,"Delivered")) | Q8: =IF(OR(A8="",E8="Dropship"),"",N(N8)+N(O8)-N(P8)) | S8: =IF(OR(A8="",E8="Dropship"),"",IF(Q8<=IF(R8="",Settings!$B$4,R8),"REORDER","OK")) | T8: =IF(OR(A8="",E8="Dropship",J8=""),"",Q8*J8)
J9: =IF(A9="","",SUM(F9:I9)) | L9: =IF(OR(A9="",K9=""),"",K9-J9) | M9: =IF(OR(A9="",K9="",K9=0),"",L9/K9) | O9: =IF(A9="","",SUMIFS('Stock In'!$C$2:$C$501,'Stock In'!$B$2:$B$501,A9)) | P9: =IF(A9="","",SUMIFS(Orders!$H$2:$H$501,Orders!$G$2:$G$501,A9,Orders!$K$2:$K$501,"Shipped")+SUMIFS(Orders!$H$2:$H$501,Orders!$G$2:$G$501,A9,Orders!$K$2:$K$501,"Delivered")) | Q9: =IF(OR(A9="",E9="Dropship"),"",N(N9)+N(O9)-N(P9)) | S9: =IF(OR(A9="",E9="Dropship"),"",IF(Q9<=IF(R9="",Settings!$B$4,R9),"REORDER","OK")) | T9: =IF(OR(A9="",E9="Dropship",J9=""),"",Q9*J9)
J10: =IF(A10="","",SUM(F10:I10)) | L10: =IF(OR(A10="",K10=""),"",K10-J10) | M10: =IF(OR(A10="",K10="",K10=0),"",L10/K10) | O10: =IF(A10="","",SUMIFS('Stock In'!$C$2:$C$501,'Stock In'!$B$2:$B$501,A10)) | P10: =IF(A10="","",SUMIFS(Orders!$H$2:$H$501,Orders!$G$2:$G$501,A10,Orders!$K$2:$K$501,"Shipped")+SUMIFS(Orders!$H$2:$H$501,Orders!$G$2:$G$501,A10,Orders!$K$2:$K$501,"Delivered")) | Q10: =IF(OR(A10="",E10="Dropship"),"",N(N10)+N(O10)-N(P10)) | S10: =IF(OR(A10="",E10="Dropship"),"",IF(Q10<=IF(R10="",Settings!$B$4,R10),"REORDER","OK")) | T10: =IF(OR(A10="",E10="Dropship",J10=""),"",Q10*J10)
J11: =IF(A11="","",SUM(F11:I11)) | L11: =IF(OR(A11="",K11=""),"",K11-J11) | M11: =IF(OR(A11="",K11="",K11=0),"",L11/K11) | O11: =IF(A11="","",SUMIFS('Stock In'!$C$2:$C$501,'Stock In'!$B$2:$B$501,A11)) | P11: =IF(A11="","",SUMIFS(Orders!$H$2:$H$501,Orders!$G$2:$G$501,A11,Orders!$K$2:$K$501,"Shipped")+SUMIFS(Orders!$H$2:$H$501,Orders!$G$2:$G$501,A11,Orders!$K$2:$K$501,"Delivered")) | Q11: =IF(OR(A11="",E11="Dropship"),"",N(N11)+N(O11)-N(P11)) | S11: =IF(OR(A11="",E11="Dropship"),"",IF(Q11<=IF(R11="",Settings!$B$4,R11),"REORDER","OK")) | T11: =IF(OR(A11="",E11="Dropship",J11=""),"",Q11*J11)
J12: =IF(A12="","",SUM(F12:I12)) | L12: =IF(OR(A12="",K12=""),"",K12-J12) | M12: =IF(OR(A12="",K12="",K12=0),"",L12/K12) | O12: =IF(A12="","",SUMIFS('Stock In'!$C$2:$C$501,'Stock In'!$B$2:$B$501,A12)) | P12: =IF(A12="","",SUMIFS(Orders!$H$2:$H$501,Orders!$G$2:$G$501,A12,Orders!$K$2:$K$501,"Shipped")+SUMIFS(Orders!$H$2:$H$501,Orders!$G$2:$G$501,A12,Orders!$K$2:$K$501,"Delivered")) | Q12: =IF(OR(A12="",E12="Dropship"),"",N(N12)+N(O12)-N(P12)) | S12: =IF(OR(A12="",E12="Dropship"),"",IF(Q12<=IF(R12="",Settings!$B$4,R12),"REORDER","OK")) | T12: =IF(OR(A12="",E12="Dropship",J12=""),"",Q12*J12)
J13: =IF(A13="","",SUM(F13:I13)) | L13: =IF(OR(A13="",K13=""),"",K13-J13) | M13: =IF(OR(A13="",K13="",K13=0),"",L13/K13) | O13: =IF(A13="","",SUMIFS('Stock In'!$C$2:$C$501,'Stock In'!$B$2:$B$501,A13)) | P13: =IF(A13="","",SUMIFS(Orders!$H$2:$H$501,Orders!$G$2:$G$501,A13,Orders!$K$2:$K$501,"Shipped")+SUMIFS(Orders!$H$2:$H$501,Orders!$G$2:$G$501,A13,Orders!$K$2:$K$501,"Delivered")) | Q13: =IF(OR(A13="",E13="Dropship"),"",N(N13)+N(O13)-N(P13)) | S13: =IF(OR(A13="",E13="Dropship"),"",IF(Q13<=IF(R13="",Settings!$B$4,R13),"REORDER","OK")) | T13: =IF(OR(A13="",E13="Dropship",J13=""),"",Q13*J13)
J14: =IF(A14="","",SUM(F14:I14)) | L14: =IF(OR(A14="",K14=""),"",K14-J14) | M14: =IF(OR(A14="",K14="",K14=0),"",L14/K14) | O14: =IF(A14="","",SUMIFS('Stock In'!$C$2:$C$501,'Stock In'!$B$2:$B$501,A14)) | P14: =IF(A14="","",SUMIFS(Orders!$H$2:$H$501,Orders!$G$2:$G$501,A14,Orders!$K$2:$K$501,"Shipped")+SUMIFS(Orders!$H$2:$H$501,Orders!$G$2:$G$501,A14,Orders!$K$2:$K$501,"Delivered")) | Q14: =IF(OR(A14="",E14="Dropship"),"",N(N14)+N(O14)-N(P14)) | S14: =IF(OR(A14="",E14="Dropship"),"",IF(Q14<=IF(R14="",Settings!$B$4,R14),"REORDER","OK")) | T14: =IF(OR(A14="",E14="Dropship",J14=""),"",Q14*J14)
J15: =IF(A15="","",SUM(F15:I15)) | L15: =IF(OR(A15="",K15=""),"",K15-J15) | M15: =IF(OR(A15="",K15="",K15=0),"",L15/K15) | O15: =IF(A15="","",SUMIFS('Stock In'!$C$2:$C$501,'Stock In'!$B$2:$B$501,A15)) | P15: =IF(A15="","",SUMIFS(Orders!$H$2:$H$501,Orders!$G$2:$G$501,A15,Orders!$K$2:$K$501,"Shipped")+SUMIFS(Orders!$H$2:$H$501,Orders!$G$2:$G$501,A15,Orders!$K$2:$K$501,"Delivered")) | Q15: =IF(OR(A15="",E15="Dropship"),"",N(N15)+N(O15)-N(P15)) | S15: =IF(OR(A15="",E15="Dropship"),"",IF(Q15<=IF(R15="",Settings!$B$4,R15),"REORDER","OK")) | T15: =IF(OR(A15="",E15="Dropship",J15=""),"",Q15*J15)
J16: =IF(A16="","",SUM(F16:I16)) | L16: =IF(OR(A16="",K16=""),"",K16-J16) | M16: =IF(OR(A16="",K16="",K16=0),"",L16/K16) | O16: =IF(A16="","",SUMIFS('Stock In'!$C$2:$C$501,'Stock In'!$B$2:$B$501,A16)) | P16: =IF(A16="","",SUMIFS(Orders!$H$2:$H$501,Orders!$G$2:$G$501,A16,Orders!$K$2:$K$501,"Shipped")+SUMIFS(Orders!$H$2:$H$501,Orders!$G$2:$G$501,A16,Orders!$K$2:$K$501,"Delivered")) | Q16: =IF(OR(A16="",E16="Dropship"),"",N(N16)+N(O16)-N(P16)) | S16: =IF(OR(A16="",E16="Dropship"),"",IF(Q16<=IF(R16="",Settings!$B$4,R16),"REORDER","OK")) | T16: =IF(OR(A16="",E16="Dropship",J16=""),"",Q16*J16)
... J101: =IF(A101="","",SUM(F101:I101)) | L101: =IF(OR(A101="",K101=""),"",K101-J101) | M101: =IF(OR(A101="",K101="",K101=0),"",L101/K101) | O101: =IF(A101="","",SUMIFS('Stock In'!$C$2:$C$501,'Stock In'!$B$2:$B$501,A101)) | P101: =IF(A101="","",SUMIFS(Orders!$H$2:$H$501,Orders!$G$2:$G$501,A101,Orders!$K$2:$K$501,"Shipped")+SUMIFS(Orders!$H$2:$H$501,Orders!$G$2:$G$501,A101,Orders!$K$2:$K$501,"Delivered")) | Q101: =IF(OR(A101="",E101="Dropship"),"",N(N101)+N(O101)-N(P101)) | S101: =IF(OR(A101="",E101="Dropship"),"",IF(Q101<=IF(R101="",Settings!$B$4,R101),"REORDER","OK")) | T101: =IF(OR(A101="",E101="Dropship",J101=""),"",Q101*J101)

Sheet Stock In
A1: Date received | B1: SKU | C1: Units received | D1: Product name | E1: Supplier / route | F1: Total cost paid (₦) | G1: Cost / unit (₦) | H1: Notes
A2: 46307 | B2: EX-EDG-01 | C2: 60 | D2: =IF(B2="","",IFERROR(INDEX(Products!$B$2:$B$101,MATCH(B2,Products!$A$2:$A$101,0)),"Unknown SKU")) | E2: Cargo agent, air, Guangzhou → Lagos | F2: 78000 | G2: =IF(OR(C2="",C2=0,F2=""),"",F2/C2) | H2: First small batch
A3: 46307 | B3: EX-SCR-01 | C3: 40 | D3: =IF(B3="","",IFERROR(INDEX(Products!$B$2:$B$101,MATCH(B3,Products!$A$2:$A$101,0)),"Unknown SKU")) | E3: Cargo agent, air, Guangzhou → Lagos | F3: 60000 | G3: =IF(OR(C3="",C3=0,F3=""),"",F3/C3)
D4: =IF(B4="","",IFERROR(INDEX(Products!$B$2:$B$101,MATCH(B4,Products!$A$2:$A$101,0)),"Unknown SKU")) | G4: =IF(OR(C4="",C4=0,F4=""),"",F4/C4)
D5: =IF(B5="","",IFERROR(INDEX(Products!$B$2:$B$101,MATCH(B5,Products!$A$2:$A$101,0)),"Unknown SKU")) | G5: =IF(OR(C5="",C5=0,F5=""),"",F5/C5)
D6: =IF(B6="","",IFERROR(INDEX(Products!$B$2:$B$101,MATCH(B6,Products!$A$2:$A$101,0)),"Unknown SKU")) | G6: =IF(OR(C6="",C6=0,F6=""),"",F6/C6)
D7: =IF(B7="","",IFERROR(INDEX(Products!$B$2:$B$101,MATCH(B7,Products!$A$2:$A$101,0)),"Unknown SKU")) | G7: =IF(OR(C7="",C7=0,F7=""),"",F7/C7)
D8: =IF(B8="","",IFERROR(INDEX(Products!$B$2:$B$101,MATCH(B8,Products!$A$2:$A$101,0)),"Unknown SKU")) | G8: =IF(OR(C8="",C8=0,F8=""),"",F8/C8)
D9: =IF(B9="","",IFERROR(INDEX(Products!$B$2:$B$101,MATCH(B9,Products!$A$2:$A$101,0)),"Unknown SKU")) | G9: =IF(OR(C9="",C9=0,F9=""),"",F9/C9)
D10: =IF(B10="","",IFERROR(INDEX(Products!$B$2:$B$101,MATCH(B10,Products!$A$2:$A$101,0)),"Unknown SKU")) | G10: =IF(OR(C10="",C10=0,F10=""),"",F10/C10)
D11: =IF(B11="","",IFERROR(INDEX(Products!$B$2:$B$101,MATCH(B11,Products!$A$2:$A$101,0)),"Unknown SKU")) | G11: =IF(OR(C11="",C11=0,F11=""),"",F11/C11)
D12: =IF(B12="","",IFERROR(INDEX(Products!$B$2:$B$101,MATCH(B12,Products!$A$2:$A$101,0)),"Unknown SKU")) | G12: =IF(OR(C12="",C12=0,F12=""),"",F12/C12)
D13: =IF(B13="","",IFERROR(INDEX(Products!$B$2:$B$101,MATCH(B13,Products!$A$2:$A$101,0)),"Unknown SKU")) | G13: =IF(OR(C13="",C13=0,F13=""),"",F13/C13)
D14: =IF(B14="","",IFERROR(INDEX(Products!$B$2:$B$101,MATCH(B14,Products!$A$2:$A$101,0)),"Unknown SKU")) | G14: =IF(OR(C14="",C14=0,F14=""),"",F14/C14)
D15: =IF(B15="","",IFERROR(INDEX(Products!$B$2:$B$101,MATCH(B15,Products!$A$2:$A$101,0)),"Unknown SKU")) | G15: =IF(OR(C15="",C15=0,F15=""),"",F15/C15)
... D501: =IF(B501="","",IFERROR(INDEX(Products!$B$2:$B$101,MATCH(B501,Products!$A$2:$A$101,0)),"Unknown SKU")) | G501: =IF(OR(C501="",C501=0,F501=""),"",F501/C501)

Sheet Orders
A1: Order ID | B1: Date | C1: Channel | D1: Customer name | E1: Phone | F1: City / area | G1: SKU | H1: Qty | I1: Unit price (₦) | J1: Product name | K1: Status | L1: Payment status | M1: Delivery fee charged (₦) | N1: Delivery cost paid (₦) | O1: Order total (₦) | P1: Channel fee (₦) | Q1: Product cost (₦) | R1: Profit (₦) | S1: New / repeat | T1: Notes
A2: CG-0001 | B2: 46298 | C2: Instagram | D2: Example customer 1 | E2: 08030000001 | F2: Lekki | G2: EX-BON-01 | H2: 2 | I2: 7500 | J2: =IF(G2="","",IFERROR(INDEX(Products!$B$2:$B$101,MATCH(G2,Products!$A$2:$A$101,0)),"Unknown SKU")) | K2: Delivered | L2: Paid | M2: 2000 | N2: 2500 | O2: =IF(OR(H2="",I2=""),"",H2*I2) | P2: =IF(O2="","",O2*IFERROR(INDEX(Settings!$B$8:$B$15,MATCH(C2,Settings!$A$8:$A$15,0)),0)) | Q2: =IF(OR(G2="",H2=""),"",H2*IFERROR(INDEX(Products!$J$2:$J$101,MATCH(G2,Products!$A$2:$A$101,0)),0)) | R2: =IF(K2="Delivered",N(O2)+N(M2)-N(N2)-N(P2)-N(Q2),IF(OR(K2="Returned",K2="Failed delivery"),-N(N2),"")) | S2: =IF(E2="","",IF(MATCH(E2,$E$2:E2,0)<ROWS($E$2:E2),"Repeat","New"))
A3: CG-0002 | B3: 46300 | C3: WhatsApp | D3: Example customer 2 | E3: 08030000002 | F3: Ikeja | G3: EX-EDG-01 | H3: 1 | I3: 5000 | J3: =IF(G3="","",IFERROR(INDEX(Products!$B$2:$B$101,MATCH(G3,Products!$A$2:$A$101,0)),"Unknown SKU")) | K3: Shipped | L3: Pay on delivery | M3: 1500 | N3: 2000 | O3: =IF(OR(H3="",I3=""),"",H3*I3) | P3: =IF(O3="","",O3*IFERROR(INDEX(Settings!$B$8:$B$15,MATCH(C3,Settings!$A$8:$A$15,0)),0)) | Q3: =IF(OR(G3="",H3=""),"",H3*IFERROR(INDEX(Products!$J$2:$J$101,MATCH(G3,Products!$A$2:$A$101,0)),0)) | R3: =IF(K3="Delivered",N(O3)+N(M3)-N(N3)-N(P3)-N(Q3),IF(OR(K3="Returned",K3="Failed delivery"),-N(N3),"")) | S3: =IF(E3="","",IF(MATCH(E3,$E$2:E3,0)<ROWS($E$2:E3),"Repeat","New"))
A4: CG-0003 | B4: 46304 | C4: Jumia | D4: Example customer 3 | E4: 08030000003 | F4: Abuja | G4: EX-SCR-01 | H4: 3 | I4: 6000 | J4: =IF(G4="","",IFERROR(INDEX(Products!$B$2:$B$101,MATCH(G4,Products!$A$2:$A$101,0)),"Unknown SKU")) | K4: Delivered | L4: Paid | M4: 0 | N4: 0 | O4: =IF(OR(H4="",I4=""),"",H4*I4) | P4: =IF(O4="","",O4*IFERROR(INDEX(Settings!$B$8:$B$15,MATCH(C4,Settings!$A$8:$A$15,0)),0)) | Q4: =IF(OR(G4="",H4=""),"",H4*IFERROR(INDEX(Products!$J$2:$J$101,MATCH(G4,Products!$A$2:$A$101,0)),0)) | R4: =IF(K4="Delivered",N(O4)+N(M4)-N(N4)-N(P4)-N(Q4),IF(OR(K4="Returned",K4="Failed delivery"),-N(N4),"")) | S4: =IF(E4="","",IF(MATCH(E4,$E$2:E4,0)<ROWS($E$2:E4),"Repeat","New"))
A5: CG-0004 | B5: 46309 | C5: Instagram | D5: Example customer 1 | E5: 08030000001 | F5: Lekki | G5: EX-SCR-01 | H5: 1 | I5: 6000 | J5: =IF(G5="","",IFERROR(INDEX(Products!$B$2:$B$101,MATCH(G5,Products!$A$2:$A$101,0)),"Unknown SKU")) | K5: Delivered | L5: Paid | M5: 2000 | N5: 2500 | O5: =IF(OR(H5="",I5=""),"",H5*I5) | P5: =IF(O5="","",O5*IFERROR(INDEX(Settings!$B$8:$B$15,MATCH(C5,Settings!$A$8:$A$15,0)),0)) | Q5: =IF(OR(G5="",H5=""),"",H5*IFERROR(INDEX(Products!$J$2:$J$101,MATCH(G5,Products!$A$2:$A$101,0)),0)) | R5: =IF(K5="Delivered",N(O5)+N(M5)-N(N5)-N(P5)-N(Q5),IF(OR(K5="Returned",K5="Failed delivery"),-N(N5),"")) | S5: =IF(E5="","",IF(MATCH(E5,$E$2:E5,0)<ROWS($E$2:E5),"Repeat","New"))
A6: CG-0005 | B6: 46311 | C6: TikTok | D6: Example customer 4 | E6: 08030000004 | F6: Yaba | G6: EX-EDG-01 | H6: 1 | I6: 5000 | J6: =IF(G6="","",IFERROR(INDEX(Products!$B$2:$B$101,MATCH(G6,Products!$A$2:$A$101,0)),"Unknown SKU")) | K6: Returned | L6: Refunded | M6: 1500 | N6: 2000 | O6: =IF(OR(H6="",I6=""),"",H6*I6) | P6: =IF(O6="","",O6*IFERROR(INDEX(Settings!$B$8:$B$15,MATCH(C6,Settings!$A$8:$A$15,0)),0)) | Q6: =IF(OR(G6="",H6=""),"",H6*IFERROR(INDEX(Products!$J$2:$J$101,MATCH(G6,Products!$A$2:$A$101,0)),0)) | R6: =IF(K6="Delivered",N(O6)+N(M6)-N(N6)-N(P6)-N(Q6),IF(OR(K6="Returned",K6="Failed delivery"),-N(N6),"")) | S6: =IF(E6="","",IF(MATCH(E6,$E$2:E6,0)<ROWS($E$2:E6),"Repeat","New"))
J7: =IF(G7="","",IFERROR(INDEX(Products!$B$2:$B$101,MATCH(G7,Products!$A$2:$A$101,0)),"Unknown SKU")) | O7: =IF(OR(H7="",I7=""),"",H7*I7) | P7: =IF(O7="","",O7*IFERROR(INDEX(Settings!$B$8:$B$15,MATCH(C7,Settings!$A$8:$A$15,0)),0)) | Q7: =IF(OR(G7="",H7=""),"",H7*IFERROR(INDEX(Products!$J$2:$J$101,MATCH(G7,Products!$A$2:$A$101,0)),0)) | R7: =IF(K7="Delivered",N(O7)+N(M7)-N(N7)-N(P7)-N(Q7),IF(OR(K7="Returned",K7="Failed delivery"),-N(N7),"")) | S7: =IF(E7="","",IF(MATCH(E7,$E$2:E7,0)<ROWS($E$2:E7),"Repeat","New"))
J8: =IF(G8="","",IFERROR(INDEX(Products!$B$2:$B$101,MATCH(G8,Products!$A$2:$A$101,0)),"Unknown SKU")) | O8: =IF(OR(H8="",I8=""),"",H8*I8) | P8: =IF(O8="","",O8*IFERROR(INDEX(Settings!$B$8:$B$15,MATCH(C8,Settings!$A$8:$A$15,0)),0)) | Q8: =IF(OR(G8="",H8=""),"",H8*IFERROR(INDEX(Products!$J$2:$J$101,MATCH(G8,Products!$A$2:$A$101,0)),0)) | R8: =IF(K8="Delivered",N(O8)+N(M8)-N(N8)-N(P8)-N(Q8),IF(OR(K8="Returned",K8="Failed delivery"),-N(N8),"")) | S8: =IF(E8="","",IF(MATCH(E8,$E$2:E8,0)<ROWS($E$2:E8),"Repeat","New"))
J9: =IF(G9="","",IFERROR(INDEX(Products!$B$2:$B$101,MATCH(G9,Products!$A$2:$A$101,0)),"Unknown SKU")) | O9: =IF(OR(H9="",I9=""),"",H9*I9) | P9: =IF(O9="","",O9*IFERROR(INDEX(Settings!$B$8:$B$15,MATCH(C9,Settings!$A$8:$A$15,0)),0)) | Q9: =IF(OR(G9="",H9=""),"",H9*IFERROR(INDEX(Products!$J$2:$J$101,MATCH(G9,Products!$A$2:$A$101,0)),0)) | R9: =IF(K9="Delivered",N(O9)+N(M9)-N(N9)-N(P9)-N(Q9),IF(OR(K9="Returned",K9="Failed delivery"),-N(N9),"")) | S9: =IF(E9="","",IF(MATCH(E9,$E$2:E9,0)<ROWS($E$2:E9),"Repeat","New"))
J10: =IF(G10="","",IFERROR(INDEX(Products!$B$2:$B$101,MATCH(G10,Products!$A$2:$A$101,0)),"Unknown SKU")) | O10: =IF(OR(H10="",I10=""),"",H10*I10) | P10: =IF(O10="","",O10*IFERROR(INDEX(Settings!$B$8:$B$15,MATCH(C10,Settings!$A$8:$A$15,0)),0)) | Q10: =IF(OR(G10="",H10=""),"",H10*IFERROR(INDEX(Products!$J$2:$J$101,MATCH(G10,Products!$A$2:$A$101,0)),0)) | R10: =IF(K10="Delivered",N(O10)+N(M10)-N(N10)-N(P10)-N(Q10),IF(OR(K10="Returned",K10="Failed delivery"),-N(N10),"")) | S10: =IF(E10="","",IF(MATCH(E10,$E$2:E10,0)<ROWS($E$2:E10),"Repeat","New"))
J11: =IF(G11="","",IFERROR(INDEX(Products!$B$2:$B$101,MATCH(G11,Products!$A$2:$A$101,0)),"Unknown SKU")) | O11: =IF(OR(H11="",I11=""),"",H11*I11) | P11: =IF(O11="","",O11*IFERROR(INDEX(Settings!$B$8:$B$15,MATCH(C11,Settings!$A$8:$A$15,0)),0)) | Q11: =IF(OR(G11="",H11=""),"",H11*IFERROR(INDEX(Products!$J$2:$J$101,MATCH(G11,Products!$A$2:$A$101,0)),0)) | R11: =IF(K11="Delivered",N(O11)+N(M11)-N(N11)-N(P11)-N(Q11),IF(OR(K11="Returned",K11="Failed delivery"),-N(N11),"")) | S11: =IF(E11="","",IF(MATCH(E11,$E$2:E11,0)<ROWS($E$2:E11),"Repeat","New"))
J12: =IF(G12="","",IFERROR(INDEX(Products!$B$2:$B$101,MATCH(G12,Products!$A$2:$A$101,0)),"Unknown SKU")) | O12: =IF(OR(H12="",I12=""),"",H12*I12) | P12: =IF(O12="","",O12*IFERROR(INDEX(Settings!$B$8:$B$15,MATCH(C12,Settings!$A$8:$A$15,0)),0)) | Q12: =IF(OR(G12="",H12=""),"",H12*IFERROR(INDEX(Products!$J$2:$J$101,MATCH(G12,Products!$A$2:$A$101,0)),0)) | R12: =IF(K12="Delivered",N(O12)+N(M12)-N(N12)-N(P12)-N(Q12),IF(OR(K12="Returned",K12="Failed delivery"),-N(N12),"")) | S12: =IF(E12="","",IF(MATCH(E12,$E$2:E12,0)<ROWS($E$2:E12),"Repeat","New"))
J13: =IF(G13="","",IFERROR(INDEX(Products!$B$2:$B$101,MATCH(G13,Products!$A$2:$A$101,0)),"Unknown SKU")) | O13: =IF(OR(H13="",I13=""),"",H13*I13) | P13: =IF(O13="","",O13*IFERROR(INDEX(Settings!$B$8:$B$15,MATCH(C13,Settings!$A$8:$A$15,0)),0)) | Q13: =IF(OR(G13="",H13=""),"",H13*IFERROR(INDEX(Products!$J$2:$J$101,MATCH(G13,Products!$A$2:$A$101,0)),0)) | R13: =IF(K13="Delivered",N(O13)+N(M13)-N(N13)-N(P13)-N(Q13),IF(OR(K13="Returned",K13="Failed delivery"),-N(N13),"")) | S13: =IF(E13="","",IF(MATCH(E13,$E$2:E13,0)<ROWS($E$2:E13),"Repeat","New"))
J14: =IF(G14="","",IFERROR(INDEX(Products!$B$2:$B$101,MATCH(G14,Products!$A$2:$A$101,0)),"Unknown SKU")) | O14: =IF(OR(H14="",I14=""),"",H14*I14) | P14: =IF(O14="","",O14*IFERROR(INDEX(Settings!$B$8:$B$15,MATCH(C14,Settings!$A$8:$A$15,0)),0)) | Q14: =IF(OR(G14="",H14=""),"",H14*IFERROR(INDEX(Products!$J$2:$J$101,MATCH(G14,Products!$A$2:$A$101,0)),0)) | R14: =IF(K14="Delivered",N(O14)+N(M14)-N(N14)-N(P14)-N(Q14),IF(OR(K14="Returned",K14="Failed delivery"),-N(N14),"")) | S14: =IF(E14="","",IF(MATCH(E14,$E$2:E14,0)<ROWS($E$2:E14),"Repeat","New"))
J15: =IF(G15="","",IFERROR(INDEX(Products!$B$2:$B$101,MATCH(G15,Products!$A$2:$A$101,0)),"Unknown SKU")) | O15: =IF(OR(H15="",I15=""),"",H15*I15) | P15: =IF(O15="","",O15*IFERROR(INDEX(Settings!$B$8:$B$15,MATCH(C15,Settings!$A$8:$A$15,0)),0)) | Q15: =IF(OR(G15="",H15=""),"",H15*IFERROR(INDEX(Products!$J$2:$J$101,MATCH(G15,Products!$A$2:$A$101,0)),0)) | R15: =IF(K15="Delivered",N(O15)+N(M15)-N(N15)-N(P15)-N(Q15),IF(OR(K15="Returned",K15="Failed delivery"),-N(N15),"")) | S15: =IF(E15="","",IF(MATCH(E15,$E$2:E15,0)<ROWS($E$2:E15),"Repeat","New"))
J16: =IF(G16="","",IFERROR(INDEX(Products!$B$2:$B$101,MATCH(G16,Products!$A$2:$A$101,0)),"Unknown SKU")) | O16: =IF(OR(H16="",I16=""),"",H16*I16) | P16: =IF(O16="","",O16*IFERROR(INDEX(Settings!$B$8:$B$15,MATCH(C16,Settings!$A$8:$A$15,0)),0)) | Q16: =IF(OR(G16="",H16=""),"",H16*IFERROR(INDEX(Products!$J$2:$J$101,MATCH(G16,Products!$A$2:$A$101,0)),0)) | R16: =IF(K16="Delivered",N(O16)+N(M16)-N(N16)-N(P16)-N(Q16),IF(OR(K16="Returned",K16="Failed delivery"),-N(N16),"")) | S16: =IF(E16="","",IF(MATCH(E16,$E$2:E16,0)<ROWS($E$2:E16),"Repeat","New"))
J17: =IF(G17="","",IFERROR(INDEX(Products!$B$2:$B$101,MATCH(G17,Products!$A$2:$A$101,0)),"Unknown SKU")) | O17: =IF(OR(H17="",I17=""),"",H17*I17) | P17: =IF(O17="","",O17*IFERROR(INDEX(Settings!$B$8:$B$15,MATCH(C17,Settings!$A$8:$A$15,0)),0)) | Q17: =IF(OR(G17="",H17=""),"",H17*IFERROR(INDEX(Products!$J$2:$J$101,MATCH(G17,Products!$A$2:$A$101,0)),0)) | R17: =IF(K17="Delivered",N(O17)+N(M17)-N(N17)-N(P17)-N(Q17),IF(OR(K17="Returned",K17="Failed delivery"),-N(N17),"")) | S17: =IF(E17="","",IF(MATCH(E17,$E$2:E17,0)<ROWS($E$2:E17),"Repeat","New"))
J18: =IF(G18="","",IFERROR(INDEX(Products!$B$2:$B$101,MATCH(G18,Products!$A$2:$A$101,0)),"Unknown SKU")) | O18: =IF(OR(H18="",I18=""),"",H18*I18) | P18: =IF(O18="","",O18*IFERROR(INDEX(Settings!$B$8:$B$15,MATCH(C18,Settings!$A$8:$A$15,0)),0)) | Q18: =IF(OR(G18="",H18=""),"",H18*IFERROR(INDEX(Products!$J$2:$J$101,MATCH(G18,Products!$A$2:$A$101,0)),0)) | R18: =IF(K18="Delivered",N(O18)+N(M18)-N(N18)-N(P18)-N(Q18),IF(OR(K18="Returned",K18="Failed delivery"),-N(N18),"")) | S18: =IF(E18="","",IF(MATCH(E18,$E$2:E18,0)<ROWS($E$2:E18),"Repeat","New"))
... J501: =IF(G501="","",IFERROR(INDEX(Products!$B$2:$B$101,MATCH(G501,Products!$A$2:$A$101,0)),"Unknown SKU")) | O501: =IF(OR(H501="",I501=""),"",H501*I501) | P501: =IF(O501="","",O501*IFERROR(INDEX(Settings!$B$8:$B$15,MATCH(C501,Settings!$A$8:$A$15,0)),0)) | Q501: =IF(OR(G501="",H501=""),"",H501*IFERROR(INDEX(Products!$J$2:$J$101,MATCH(G501,Products!$A$2:$A$101,0)),0)) | R501: =IF(K501="Delivered",N(O501)+N(M501)-N(N501)-N(P501)-N(Q501),IF(OR(K501="Returned",K501="Failed delivery"),-N(N501),"")) | S501: =IF(E501="","",IF(MATCH(E501,$E$2:E501,0)<ROWS($E$2:E501),"Repeat","New"))

Sheet Expenses
A1: Date | B1: Category | C1: Description | D1: Amount (₦) | E1: Channel (if any) | F1: Notes
A2: 46296 | B2: Samples | C2: Samples of 3 products + shipping | D2: 18000
A3: 46299 | B3: Ads | C3: Instagram ad: bonnet video | D3: 25000 | E3: Instagram
A4: 46305 | B4: Packaging | C4: Branded mailer bags (100) | D4: 12000
